[2023-06-22 12:49:05 +0800] [17123] [DEBUG] 

                 Sanic
         Build Fast. Run Fast.


[2023-06-22 12:49:05 +0800] [17123] [INFO] Sanic v23.3.0
[2023-06-22 12:49:05 +0800] [17123] [INFO] Goin' Fast @ http://0.0.0.0:13137
[2023-06-22 12:49:05 +0800] [17123] [INFO] mode: debug, single worker
[2023-06-22 12:49:05 +0800] [17123] [INFO] server: sanic, HTTP/1.1
[2023-06-22 12:49:05 +0800] [17123] [INFO] python: 3.9.2
[2023-06-22 12:49:05 +0800] [17123] [INFO] platform: Linux-5.19.0-0.deb11.2-amd64-x86_64-with-glibc2.31
[2023-06-22 12:49:05 +0800] [17123] [INFO] auto-reload: enabled
[2023-06-22 12:49:05 +0800] [17123] [INFO] packages: sanic-routing==22.8.0, sanic-ext==23.3.0
[2023-06-22 12:49:05 +0800] [17123] [DEBUG] Creating multiprocessing context using 'spawn'
[2023-06-22 12:49:05 +0800] [17123] [DEBUG] [34mStarting a process: [1m[38;2;255;13;104mSanic-Server-0-0[0m
[2023-06-22 12:49:05 +0800] [17123] [DEBUG] [34mStarting a process: [1m[38;2;255;13;104mSanic-Reloader-0[0m
[2023-06-22 12:49:09 +0800] [17134] [INFO] Sanic Extensions:
[2023-06-22 12:49:09 +0800] [17134] [INFO]   > injection [0 dependencies; 0 constants]
[2023-06-22 12:49:09 +0800] [17134] [INFO]   > openapi [http://0.0.0.0:13137/docs]
[2023-06-22 12:49:09 +0800] [17134] [INFO]   > http 
[2023-06-22 12:49:09 +0800] [17134] [INFO]   > templating [jinja2==3.1.2]
Executing <Task finished name='Task-2' coro=<Sanic._server_event() done, defined at /home/ljp/.local/lib/python3.9/site-packages/sanic/app.py:1612> result=None created at /home/ljp/.local/lib/python3.9/site-packages/sanic/server/runners.py:225> took 0.769 seconds
[2023-06-22 12:49:09 +0800] [17134] [DEBUG] [34mProcess ack: [1m[38;2;255;13;104mSanic-Server-0-0 [34m[17134][0m
[2023-06-22 12:49:09 +0800] [17134] [INFO] Starting worker [17134]
[2023-06-22 13:12:45 +0800] [17123] [INFO] Received signal SIGTERM. Shutting down.
[2023-06-22 13:12:45 +0800] [17123] [DEBUG] [34mTerminating a process: [1m[38;2;255;13;104mSanic-Server-0-0 [34m[17134][0m
[2023-06-22 13:12:45 +0800] [17123] [ERROR] Experienced exception while trying to serve
Traceback (most recent call last):
  File "/home/ljp/.local/lib/python3.9/site-packages/sanic/mixins/startup.py", line 853, in serve
    manager.run()
  File "/home/ljp/.local/lib/python3.9/site-packages/sanic/worker/manager.py", line 122, in run
    self.monitor()
  File "/home/ljp/.local/lib/python3.9/site-packages/sanic/worker/manager.py", line 186, in monitor
    if self.monitor_subscriber.poll(0.1):
  File "/usr/lib/python3.9/multiprocessing/connection.py", line 262, in poll
    return self._poll(timeout)
  File "/usr/lib/python3.9/multiprocessing/connection.py", line 429, in _poll
    r = wait([self], timeout)
  File "/usr/lib/python3.9/multiprocessing/connection.py", line 936, in wait
    ready = selector.select(timeout)
  File "/usr/lib/python3.9/selectors.py", line 416, in select
    fd_event_list = self._selector.poll(timeout)
  File "/home/ljp/.local/lib/python3.9/site-packages/sanic/worker/manager.py", line 293, in shutdown_signal
    self.shutdown()
  File "/home/ljp/.local/lib/python3.9/site-packages/sanic/worker/manager.py", line 298, in shutdown
    process.terminate()
  File "/home/ljp/.local/lib/python3.9/site-packages/sanic/worker/process.py", line 77, in terminate
    self.set_state(ProcessState.TERMINATED, force=True)
  File "/home/ljp/.local/lib/python3.9/site-packages/sanic/worker/process.py", line 41, in set_state
    **self.worker_state[self.name],
  File "<string>", line 2, in __getitem__
  File "/usr/lib/python3.9/multiprocessing/managers.py", line 809, in _callmethod
    kind, result = conn.recv()
  File "/usr/lib/python3.9/multiprocessing/connection.py", line 255, in recv
    buf = self._recv_bytes()
  File "/usr/lib/python3.9/multiprocessing/connection.py", line 419, in _recv_bytes
    buf = self._recv(4)
  File "/usr/lib/python3.9/multiprocessing/connection.py", line 384, in _recv
    chunk = read(handle, remaining)
ConnectionResetError: [Errno 104] Connection reset by peer
[2023-06-22 13:12:45 +0800] [17123] [INFO] Server Stopped
Traceback (most recent call last):
  File "/home/ljp/dev/sxhwdata/app.py", line 9, in <module>
    app.run(host='0.0.0.0', port=13137, dev=True)
  File "/home/ljp/.local/lib/python3.9/site-packages/sanic/mixins/startup.py", line 204, in run
    serve(primary=self)  # type: ignore
  File "/home/ljp/.local/lib/python3.9/site-packages/sanic/mixins/startup.py", line 853, in serve
    manager.run()
  File "/home/ljp/.local/lib/python3.9/site-packages/sanic/worker/manager.py", line 122, in run
    self.monitor()
  File "/home/ljp/.local/lib/python3.9/site-packages/sanic/worker/manager.py", line 186, in monitor
    if self.monitor_subscriber.poll(0.1):
  File "/usr/lib/python3.9/multiprocessing/connection.py", line 262, in poll
    return self._poll(timeout)
  File "/usr/lib/python3.9/multiprocessing/connection.py", line 429, in _poll
    r = wait([self], timeout)
  File "/usr/lib/python3.9/multiprocessing/connection.py", line 936, in wait
    ready = selector.select(timeout)
  File "/usr/lib/python3.9/selectors.py", line 416, in select
    fd_event_list = self._selector.poll(timeout)
  File "/home/ljp/.local/lib/python3.9/site-packages/sanic/worker/manager.py", line 293, in shutdown_signal
    self.shutdown()
  File "/home/ljp/.local/lib/python3.9/site-packages/sanic/worker/manager.py", line 298, in shutdown
    process.terminate()
  File "/home/ljp/.local/lib/python3.9/site-packages/sanic/worker/process.py", line 77, in terminate
    self.set_state(ProcessState.TERMINATED, force=True)
  File "/home/ljp/.local/lib/python3.9/site-packages/sanic/worker/process.py", line 41, in set_state
    **self.worker_state[self.name],
  File "<string>", line 2, in __getitem__
  File "/usr/lib/python3.9/multiprocessing/managers.py", line 809, in _callmethod
    kind, result = conn.recv()
  File "/usr/lib/python3.9/multiprocessing/connection.py", line 255, in recv
    buf = self._recv_bytes()
  File "/usr/lib/python3.9/multiprocessing/connection.py", line 419, in _recv_bytes
    buf = self._recv(4)
  File "/usr/lib/python3.9/multiprocessing/connection.py", line 384, in _recv
    chunk = read(handle, remaining)
ConnectionResetError: [Errno 104] Connection reset by peer
[2023-06-22 13:12:45 +0800] [17134] [INFO] Stopping worker [17134]
